Workbook

Sheet Guide
B1: EMPLOYEE MASTER TEMPLATE - START HERE
B2: Employee records with a dashboard and a printable employee card. Empty and ready to fill - no employee data inside.
B4: SHEETS
B5: Dashboard | C5: Live numbers: headcount, payroll, department and location tables, gender / age / tenure mix, birthdays, work anniversaries and data-quality counts. Nothing to type.
B6: Employee Master | C6: One row per employee (500 rows ready): job, personal, contact, address, bank & statutory and salary details.
B7: Employee Card | C7: Pick an Emp Code to get a one-page printable profile.
B8: Settings | C8: Company name, report date and the confirmation period (days) that decides Permanent vs Probation.
B9: Lists | C9: Dropdown options (Department, Location, Designation, Bank, State ...). Overwrite the examples with your own.
B11: HOW TO USE
B12: 1. Settings | C12: Type your Company name.
B13: 2. Lists | C13: Replace the example Departments, Locations and Designations with your own.
B14: 3. Add employees | C14: Employee Master > first blank row from row 6. Paste values only (Paste Special > Values) to keep dropdowns and formulas.
B15: Employment Type | C15: Automatic: Permanent once an employee is 90 days or more past the Date of Joining, otherwise Probation (change the days in Settings).
B16: Record an exit | C16: Type the Exit Date (and Exit Reason). Status becomes Exited and the row turns grey.
B17: Salary revision | C17: Move the old amount to Previous Salary, enter the new amount in Current Salary and the Last Revision Date. Hike % is automatic.
B18: Data quality | C18: Pink cells = active employee with missing Aadhaar, PAN, mobile, bank account or IFSC. "Data Issue Details" explains each row.
B20: COLOUR GUIDE
B21: Yellow cell, blue text | C21: Input cell on Settings / Dashboard / Card - type here.
B22: Blue text, white cell | C22: Input column in Employee Master - type here.
B23: Blue-grey cell | C23: Calculated automatically - do not type over it.
B24: Pink / amber cell | C24: Missing or invalid details (see Data Issue Details).
B25: Grey italic row | C25: Exited employee.
B27: EXAMPLE ENTRY (format only - fictional values, do not copy into the sheet)
B28: Emp Code / Name | C28: EMP001 / Asha Mehta
B29: DOJ / DOB | C29: 01-Apr-2024 / 15-Aug-1995 (type as a date)
B30: Aadhaar / PAN / Mobile | C30: 123412341234 (12 digits) / ABCDE1234F (10 characters) / 9876543210 (10 digits)
B31: Bank A/c / IFSC | C31: 1234567890 / SBIN0001234 (11 characters)
B33: LIMITS
B34: Capacity | C34: Employee Master: 500 employees. Dropdowns: 12 departments, 10 locations, 40 designations.

Sheet Dashboard
B1: ="EMPLOYEE DASHBOARD - "&Settings!$C$5 -> EMPLOYEE DASHBOARD - Your Company Name
B2: ="As of "&TEXT(AsOf,"dd-mmm-yyyy")&" | Financial year "&CurFY&" | All figures are live from the Employee Master sheet" -> As of 27-Oct-2026 | Financial year 2026-27 | All figures are live from the Employee Master sheet
B4: Total Records | D4: Active Headcount | F4: Exited (all time) | H4: Avg Tenure - Active (yrs) | J4: Avg Age - Active (yrs) | L4: Monthly Payroll - Active (Rs) | N4: Avg Salary - Active (Rs)
B5: =COUNTA(M_emp) -> 0 | D5: =COUNTIF(M_status,"Active") -> 0 | F5: =COUNTIF(M_status,"Exited") -> 0 | H5: =IFERROR(AVERAGEIFS(M_ten,M_status,"Active"),0) -> 0 | J5: =IFERROR(AVERAGEIFS(M_age,M_status,"Active"),0) -> 0 | L5: =SUMIFS(M_sal,M_status,"Active") -> 0 | N5: =IFERROR(SUMIFS(M_sal,M_status,"Active")/COUNTIF(M_status,"Active"),0) -> 0
B7: Female % of Active | D7: Joined this FY | F7: Exited this FY | H7: Exit % this FY | J7: Birthdays in alert window | L7: Work anniversaries in window | N7: Active records with data issues
B8: =IFERROR(COUNTIFS(M_status,"Active",M_sex,"Female")/COUNTIF(M_status,"Active"),0) -> 0 | D8: =COUNTIF(M_fyin,CurFY) -> 0 | F8: =COUNTIF(M_fyout,CurFY) -> 0 | H8: =IFERROR(COUNTIF(M_fyout,CurFY)/(COUNTIF(M_status,"Active")+COUNTIF(M_fyout,CurFY)),0) -> 0 | J8: =COUNTIF(M_bd,"<="&Settings!$C$18) -> 0 | L8: =COUNTIF(M_an,"<="&Settings!$C$18) -> 0 | N8: =COUNTIFS(M_status,"Active",M_issues,">0") -> 0
B10: DEPARTMENT SUMMARY | I10: LOCATION SUMMARY
B11: Department | C11: Active | D11: % of Active | E11: Monthly Payroll (Rs) | F11: Avg Salary (Rs) | G11: Exited | I11: Location | J11: Active | K11: Exited | L11: Monthly Payroll (Rs)
B12: =IF(Lists!A5="","",Lists!A5) -> Admin | C12: =IF($B12="","",COUNTIFS(M_dept,$B12,M_status,"Active")) -> 0 | D12: =IF($B12="","",IFERROR(C12/C$24,0)) -> 0 | E12: =IF($B12="","",SUMIFS(M_sal,M_dept,$B12,M_status,"Active")) -> 0 | F12: =IF($B12="","",IFERROR(E12/C12,0)) -> 0 | G12: =IF($B12="","",COUNTIFS(M_dept,$B12,M_status,"Exited")) -> 0 | I12: =IF(Lists!B5="","",Lists!B5) -> Location 1 | J12: =IF($I12="","",COUNTIFS(M_loc,$I12,M_status,"Active")) -> 0 | K12: =IF($I12="","",COUNTIFS(M_loc,$I12,M_status,"Exited")) -> 0 | L12: =IF($I12="","",SUMIFS(M_sal,M_loc,$I12,M_status,"Active")) -> 0
B13: =IF(Lists!A6="","",Lists!A6) -> Accounts | C13: =IF($B13="","",COUNTIFS(M_dept,$B13,M_status,"Active")) -> 0 | D13: =IF($B13="","",IFERROR(C13/C$24,0)) -> 0 | E13: =IF($B13="","",SUMIFS(M_sal,M_dept,$B13,M_status,"Active")) -> 0 | F13: =IF($B13="","",IFERROR(E13/C13,0)) -> 0 | G13: =IF($B13="","",COUNTIFS(M_dept,$B13,M_status,"Exited")) -> 0 | I13: =IF(Lists!B6="","",Lists!B6) -> Location 2 | J13: =IF($I13="","",COUNTIFS(M_loc,$I13,M_status,"Active")) -> 0 | K13: =IF($I13="","",COUNTIFS(M_loc,$I13,M_status,"Exited")) -> 0 | L13: =IF($I13="","",SUMIFS(M_sal,M_loc,$I13,M_status,"Active")) -> 0
B14: =IF(Lists!A7="","",Lists!A7) -> HR | C14: =IF($B14="","",COUNTIFS(M_dept,$B14,M_status,"Active")) -> 0 | D14: =IF($B14="","",IFERROR(C14/C$24,0)) -> 0 | E14: =IF($B14="","",SUMIFS(M_sal,M_dept,$B14,M_status,"Active")) -> 0 | F14: =IF($B14="","",IFERROR(E14/C14,0)) -> 0 | G14: =IF($B14="","",COUNTIFS(M_dept,$B14,M_status,"Exited")) -> 0 | I14: =IF(Lists!B7="","",Lists!B7) | J14: =IF($I14="","",COUNTIFS(M_loc,$I14,M_status,"Active")) | K14: =IF($I14="","",COUNTIFS(M_loc,$I14,M_status,"Exited")) | L14: =IF($I14="","",SUMIFS(M_sal,M_loc,$I14,M_status,"Active"))
B15: =IF(Lists!A8="","",Lists!A8) -> IT | C15: =IF($B15="","",COUNTIFS(M_dept,$B15,M_status,"Active")) -> 0 | D15: =IF($B15="","",IFERROR(C15/C$24,0)) -> 0 | E15: =IF($B15="","",SUMIFS(M_sal,M_dept,$B15,M_status,"Active")) -> 0 | F15: =IF($B15="","",IFERROR(E15/C15,0)) -> 0 | G15: =IF($B15="","",COUNTIFS(M_dept,$B15,M_status,"Exited")) -> 0 | I15: =IF(Lists!B8="","",Lists!B8) | J15: =IF($I15="","",COUNTIFS(M_loc,$I15,M_status,"Active")) | K15: =IF($I15="","",COUNTIFS(M_loc,$I15,M_status,"Exited")) | L15: =IF($I15="","",SUMIFS(M_sal,M_loc,$I15,M_status,"Active"))
B16: =IF(Lists!A9="","",Lists!A9) -> Operations | C16: =IF($B16="","",COUNTIFS(M_dept,$B16,M_status,"Active")) -> 0 | D16: =IF($B16="","",IFERROR(C16/C$24,0)) -> 0 | E16: =IF($B16="","",SUMIFS(M_sal,M_dept,$B16,M_status,"Active")) -> 0 | F16: =IF($B16="","",IFERROR(E16/C16,0)) -> 0 | G16: =IF($B16="","",COUNTIFS(M_dept,$B16,M_status,"Exited")) -> 0 | I16: =IF(Lists!B9="","",Lists!B9) | J16: =IF($I16="","",COUNTIFS(M_loc,$I16,M_status,"Active")) | K16: =IF($I16="","",COUNTIFS(M_loc,$I16,M_status,"Exited")) | L16: =IF($I16="","",SUMIFS(M_sal,M_loc,$I16,M_status,"Active"))
B17: =IF(Lists!A10="","",Lists!A10) -> Production | C17: =IF($B17="","",COUNTIFS(M_dept,$B17,M_status,"Active")) -> 0 | D17: =IF($B17="","",IFERROR(C17/C$24,0)) -> 0 | E17: =IF($B17="","",SUMIFS(M_sal,M_dept,$B17,M_status,"Active")) -> 0 | F17: =IF($B17="","",IFERROR(E17/C17,0)) -> 0 | G17: =IF($B17="","",COUNTIFS(M_dept,$B17,M_status,"Exited")) -> 0 | I17: =IF(Lists!B10="","",Lists!B10) | J17: =IF($I17="","",COUNTIFS(M_loc,$I17,M_status,"Active")) | K17: =IF($I17="","",COUNTIFS(M_loc,$I17,M_status,"Exited")) | L17: =IF($I17="","",SUMIFS(M_sal,M_loc,$I17,M_status,"Active"))
B18: =IF(Lists!A11="","",Lists!A11) -> Sales | C18: =IF($B18="","",COUNTIFS(M_dept,$B18,M_status,"Active")) -> 0 | D18: =IF($B18="","",IFERROR(C18/C$24,0)) -> 0 | E18: =IF($B18="","",SUMIFS(M_sal,M_dept,$B18,M_status,"Active")) -> 0 | F18: =IF($B18="","",IFERROR(E18/C18,0)) -> 0 | G18: =IF($B18="","",COUNTIFS(M_dept,$B18,M_status,"Exited")) -> 0 | I18: =IF(Lists!B11="","",Lists!B11) | J18: =IF($I18="","",COUNTIFS(M_loc,$I18,M_status,"Active")) | K18: =IF($I18="","",COUNTIFS(M_loc,$I18,M_status,"Exited")) | L18: =IF($I18="","",SUMIFS(M_sal,M_loc,$I18,M_status,"Active"))
B19: =IF(Lists!A12="","",Lists!A12) -> Stores | C19: =IF($B19="","",COUNTIFS(M_dept,$B19,M_status,"Active")) -> 0 | D19: =IF($B19="","",IFERROR(C19/C$24,0)) -> 0 | E19: =IF($B19="","",SUMIFS(M_sal,M_dept,$B19,M_status,"Active")) -> 0 | F19: =IF($B19="","",IFERROR(E19/C19,0)) -> 0 | G19: =IF($B19="","",COUNTIFS(M_dept,$B19,M_status,"Exited")) -> 0 | I19: =IF(Lists!B12="","",Lists!B12) | J19: =IF($I19="","",COUNTIFS(M_loc,$I19,M_status,"Active")) | K19: =IF($I19="","",COUNTIFS(M_loc,$I19,M_status,"Exited")) | L19: =IF($I19="","",SUMIFS(M_sal,M_loc,$I19,M_status,"Active"))
B20: =IF(Lists!A13="","",Lists!A13) | C20: =IF($B20="","",COUNTIFS(M_dept,$B20,M_status,"Active")) | D20: =IF($B20="","",IFERROR(C20/C$24,0)) | E20: =IF($B20="","",SUMIFS(M_sal,M_dept,$B20,M_status,"Active")) | F20: =IF($B20="","",IFERROR(E20/C20,0)) | G20: =IF($B20="","",COUNTIFS(M_dept,$B20,M_status,"Exited")) | I20: =IF(Lists!B13="","",Lists!B13) | J20: =IF($I20="","",COUNTIFS(M_loc,$I20,M_status,"Active")) | K20: =IF($I20="","",COUNTIFS(M_loc,$I20,M_status,"Exited")) | L20: =IF($I20="","",SUMIFS(M_sal,M_loc,$I20,M_status,"Active"))
B21: =IF(Lists!A14="","",Lists!A14) | C21: =IF($B21="","",COUNTIFS(M_dept,$B21,M_status,"Active")) | D21: =IF($B21="","",IFERROR(C21/C$24,0)) | E21: =IF($B21="","",SUMIFS(M_sal,M_dept,$B21,M_status,"Active")) | F21: =IF($B21="","",IFERROR(E21/C21,0)) | G21: =IF($B21="","",COUNTIFS(M_dept,$B21,M_status,"Exited")) | I21: =IF(Lists!B14="","",Lists!B14) | J21: =IF($I21="","",COUNTIFS(M_loc,$I21,M_status,"Active")) | K21: =IF($I21="","",COUNTIFS(M_loc,$I21,M_status,"Exited")) | L21: =IF($I21="","",SUMIFS(M_sal,M_loc,$I21,M_status,"Active"))
B22: =IF(Lists!A15="","",Lists!A15) | C22: =IF($B22="","",COUNTIFS(M_dept,$B22,M_status,"Active")) | D22: =IF($B22="","",IFERROR(C22/C$24,0)) | E22: =IF($B22="","",SUMIFS(M_sal,M_dept,$B22,M_status,"Active")) | F22: =IF($B22="","",IFERROR(E22/C22,0)) | G22: =IF($B22="","",COUNTIFS(M_dept,$B22,M_status,"Exited")) | I22: TOTAL | J22: =SUM(J12:J21) -> 0 | K22: =SUM(K12:K21) -> 0 | L22: =SUM(L12:L21) -> 0
B23: =IF(Lists!A16="","",Lists!A16) | C23: =IF($B23="","",COUNTIFS(M_dept,$B23,M_status,"Active")) | D23: =IF($B23="","",IFERROR(C23/C$24,0)) | E23: =IF($B23="","",SUMIFS(M_sal,M_dept,$B23,M_status,"Active")) | F23: =IF($B23="","",IFERROR(E23/C23,0)) | G23: =IF($B23="","",COUNTIFS(M_dept,$B23,M_status,"Exited")) | I23: ="Active employees with no / unlisted location: "&(D5-J22) -> Active employees with no / unlisted location: 0
B24: TOTAL | C24: =SUM(C12:C23) -> 0 | D24: =SUM(D12:D23) -> 0 | E24: =SUM(E12:E23) -> 0 | F24: =IFERROR(E24/C24,0) -> 0 | G24: =SUM(G12:G23) -> 0
B25: ="Active employees with no / unlisted department: "&(D5-C24) -> Active employees with no / unlisted department: 0
B27: WORKFORCE MIX (ACTIVE EMPLOYEES)
B28: Gender | C28: Count | E28: Employment Type | F28: Count | H28: Age Band | I28: Count | K28: Tenure Band | L28: Count
B29: =IF(Lists!D5="","",Lists!D5) -> Male | C29: =IF(B29="","",COUNTIFS(M_sex,B29,M_status,"Active")) -> 0 | E29: =IF(Lists!G5="","",Lists!G5) -> Permanent | F29: =IF(E29="","",COUNTIFS(M_type,E29,M_status,"Active")) -> 0 | H29: Below 25 | I29: =COUNTIFS(M_status,"Active",M_age,"<25") -> 0 | K29: Below 1 yr | L29: =COUNTIFS(M_status,"Active",M_ten,"<1") -> 0
B30: =IF(Lists!D6="","",Lists!D6) -> Female | C30: =IF(B30="","",COUNTIFS(M_sex,B30,M_status,"Active")) -> 0 | E30: =IF(Lists!G6="","",Lists!G6) -> Probation | F30: =IF(E30="","",COUNTIFS(M_type,E30,M_status,"Active")) -> 0 | H30: 25 - 34 | I30: =COUNTIFS(M_status,"Active",M_age,">=25",M_age,"<=34") -> 0 | K30: 1 - 3 yrs | L30: =COUNTIFS(M_status,"Active",M_ten,">=1",M_ten,"<3") -> 0
B31: =IF(Lists!D7="","",Lists!D7) -> Other | C31: =IF(B31="","",COUNTIFS(M_sex,B31,M_status,"Active")) -> 0 | E31: =IF(Lists!G7="","",Lists!G7) | F31: =IF(E31="","",COUNTIFS(M_type,E31,M_status,"Active")) | H31: 35 - 44 | I31: =COUNTIFS(M_status,"Active",M_age,">=35",M_age,"<=44") -> 0 | K31: 3 - 5 yrs | L31: =COUNTIFS(M_status,"Active",M_ten,">=3",M_ten,"<5") -> 0
E32: =IF(Lists!G8="","",Lists!G8) | F32: =IF(E32="","",COUNTIFS(M_type,E32,M_status,"Active")) | H32: 45 - 54 | I32: =COUNTIFS(M_status,"Active",M_age,">=45",M_age,"<=54") -> 0 | K32: 5 - 10 yrs | L32: =COUNTIFS(M_status,"Active",M_ten,">=5",M_ten,"<10") -> 0
E33: =IF(Lists!G9="","",Lists!G9) | F33: =IF(E33="","",COUNTIFS(M_type,E33,M_status,"Active")) | H33: 55 & above | I33: =COUNTIFS(M_status,"Active",M_age,">=55") -> 0 | K33: 10+ yrs | L33: =COUNTIFS(M_status,"Active",M_ten,">=10") -> 0
E34: =IF(Lists!G10="","",Lists!G10) | F34: =IF(E34="","",COUNTIFS(M_type,E34,M_status,"Active"))
B37: UPCOMING BIRTHDAYS (next 5) | H37: UPCOMING WORK ANNIVERSARIES (next 5)
B38: Name | C38: Department | D38: Date | E38: In (days) | H38: Name | J38: Department | K38: Date | L38: Years | M38: In (days)
B39: =IFERROR(INDEX(M_name,MATCH(SMALL(M_bdrank,ROWS(B$39:B39)),M_bdrank,0)),"") | C39: =IFERROR(INDEX(M_dept,MATCH(SMALL(M_bdrank,ROWS(B$39:B39)),M_bdrank,0)),"") | D39: =IFERROR(AsOf+INDEX(M_bd,MATCH(SMALL(M_bdrank,ROWS(B$39:B39)),M_bdrank,0)),"") | E39: =IFERROR(INDEX(M_bd,MATCH(SMALL(M_bdrank,ROWS(B$39:B39)),M_bdrank,0)),"") | H39: =IFERROR(INDEX(M_name,MATCH(SMALL(M_anrank,ROWS(H$39:H39)),M_anrank,0)),"") | J39: =IFERROR(INDEX(M_dept,MATCH(SMALL(M_anrank,ROWS(H$39:H39)),M_anrank,0)),"") | K39: =IFERROR(AsOf+INDEX(M_an,MATCH(SMALL(M_anrank,ROWS(H$39:H39)),M_anrank,0)),"") | L39: =IFERROR(YEAR(K39)-YEAR(INDEX(M_doj,MATCH(SMALL(M_anrank,ROWS(H$39:H39)),M_anrank,0))),"") | M39: =IFERROR(INDEX(M_an,MATCH(SMALL(M_anrank,ROWS(H$39:H39)),M_anrank,0)),"")
B40: =IFERROR(INDEX(M_name,MATCH(SMALL(M_bdrank,ROWS(B$39:B40)),M_bdrank,0)),"") | C40: =IFERROR(INDEX(M_dept,MATCH(SMALL(M_bdrank,ROWS(B$39:B40)),M_bdrank,0)),"") | D40: =IFERROR(AsOf+INDEX(M_bd,MATCH(SMALL(M_bdrank,ROWS(B$39:B40)),M_bdrank,0)),"") | E40: =IFERROR(INDEX(M_bd,MATCH(SMALL(M_bdrank,ROWS(B$39:B40)),M_bdrank,0)),"") | H40: =IFERROR(INDEX(M_name,MATCH(SMALL(M_anrank,ROWS(H$39:H40)),M_anrank,0)),"") | J40: =IFERROR(INDEX(M_dept,MATCH(SMALL(M_anrank,ROWS(H$39:H40)),M_anrank,0)),"") | K40: =IFERROR(AsOf+INDEX(M_an,MATCH(SMALL(M_anrank,ROWS(H$39:H40)),M_anrank,0)),"") | L40: =IFERROR(YEAR(K40)-YEAR(INDEX(M_doj,MATCH(SMALL(M_anrank,ROWS(H$39:H40)),M_anrank,0))),"") | M40: =IFERROR(INDEX(M_an,MATCH(SMALL(M_anrank,ROWS(H$39:H40)),M_anrank,0)),"")
B41: =IFERROR(INDEX(M_name,MATCH(SMALL(M_bdrank,ROWS(B$39:B41)),M_bdrank,0)),"") | C41: =IFERROR(INDEX(M_dept,MATCH(SMALL(M_bdrank,ROWS(B$39:B41)),M_bdrank,0)),"") | D41: =IFERROR(AsOf+INDEX(M_bd,MATCH(SMALL(M_bdrank,ROWS(B$39:B41)),M_bdrank,0)),"") | E41: =IFERROR(INDEX(M_bd,MATCH(SMALL(M_bdrank,ROWS(B$39:B41)),M_bdrank,0)),"") | H41: =IFERROR(INDEX(M_name,MATCH(SMALL(M_anrank,ROWS(H$39:H41)),M_anrank,0)),"") | J41: =IFERROR(INDEX(M_dept,MATCH(SMALL(M_anrank,ROWS(H$39:H41)),M_anrank,0)),"") | K41: =IFERROR(AsOf+INDEX(M_an,MATCH(SMALL(M_anrank,ROWS(H$39:H41)),M_anrank,0)),"") | L41: =IFERROR(YEAR(K41)-YEAR(INDEX(M_doj,MATCH(SMALL(M_anrank,ROWS(H$39:H41)),M_anrank,0))),"") | M41: =IFERROR(INDEX(M_an,MATCH(SMALL(M_anrank,ROWS(H$39:H41)),M_anrank,0)),"")
B42: =IFERROR(INDEX(M_name,MATCH(SMALL(M_bdrank,ROWS(B$39:B42)),M_bdrank,0)),"") | C42: =IFERROR(INDEX(M_dept,MATCH(SMALL(M_bdrank,ROWS(B$39:B42)),M_bdrank,0)),"") | D42: =IFERROR(AsOf+INDEX(M_bd,MATCH(SMALL(M_bdrank,ROWS(B$39:B42)),M_bdrank,0)),"") | E42: =IFERROR(INDEX(M_bd,MATCH(SMALL(M_bdrank,ROWS(B$39:B42)),M_bdrank,0)),"") | H42: =IFERROR(INDEX(M_name,MATCH(SMALL(M_anrank,ROWS(H$39:H42)),M_anrank,0)),"") | J42: =IFERROR(INDEX(M_dept,MATCH(SMALL(M_anrank,ROWS(H$39:H42)),M_anrank,0)),"") | K42: =IFERROR(AsOf+INDEX(M_an,MATCH(SMALL(M_anrank,ROWS(H$39:H42)),M_anrank,0)),"") | L42: =IFERROR(YEAR(K42)-YEAR(INDEX(M_doj,MATCH(SMALL(M_anrank,ROWS(H$39:H42)),M_anrank,0))),"") | M42: =IFERROR(INDEX(M_an,MATCH(SMALL(M_anrank,ROWS(H$39:H42)),M_anrank,0)),"")
B43: =IFERROR(INDEX(M_name,MATCH(SMALL(M_bdrank,ROWS(B$39:B43)),M_bdrank,0)),"") | C43: =IFERROR(INDEX(M_dept,MATCH(SMALL(M_bdrank,ROWS(B$39:B43)),M_bdrank,0)),"") | D43: =IFERROR(AsOf+INDEX(M_bd,MATCH(SMALL(M_bdrank,ROWS(B$39:B43)),M_bdrank,0)),"") | E43: =IFERROR(INDEX(M_bd,MATCH(SMALL(M_bdrank,ROWS(B$39:B43)),M_bdrank,0)),"") | H43: =IFERROR(INDEX(M_name,MATCH(SMALL(M_anrank,ROWS(H$39:H43)),M_anrank,0)),"") | J43: =IFERROR(INDEX(M_dept,MATCH(SMALL(M_anrank,ROWS(H$39:H43)),M_anrank,0)),"") | K43: =IFERROR(AsOf+INDEX(M_an,MATCH(SMALL(M_anrank,ROWS(H$39:H43)),M_anrank,0)),"") | L43: =IFERROR(YEAR(K43)-YEAR(INDEX(M_doj,MATCH(SMALL(M_anrank,ROWS(H$39:H43)),M_anrank,0))),"") | M43: =IFERROR(INDEX(M_an,MATCH(SMALL(M_anrank,ROWS(H$39:H43)),M_anrank,0)),"")
B46: DATA QUALITY - active employees with missing details
B47: Missing Aadhaar | D47: Missing PAN | F47: Missing Mobile | H47: Missing Bank A/c | J47: Missing IFSC | L47: Missing DOB | N47: Missing DOJ
B48: =COUNTIFS(M_status,"Active",M_aadhaar,"") -> 0 | D48: =COUNTIFS(M_status,"Active",M_pan,"") -> 0 | F48: =COUNTIFS(M_status,"Active",M_mobile,"") -> 0 | H48: =COUNTIFS(M_status,"Active",M_acct,"") -> 0 | J48: =COUNTIFS(M_status,"Active",M_ifsc,"") -> 0 | L48: =COUNTIFS(M_status,"Active",M_dob,"") -> 0 | N48: =COUNTIFS(M_status,"Active",M_doj,"") -> 0
...

Sheet Employee Master
A1: ="EMPLOYEE MASTER - "&Settings!$C$5 -> EMPLOYEE MASTER - Your Company Name
A2: How to use: type each employee in the first blank row (blue text = input, blue-grey columns fill themselves, incl. Employment Type: Permanent after 90 days from DOJ, else Probation). To record an exit, type the Exit Date - Status turns to Exited. Dropdown options come from the Lists sheet.
B3: Active | C3: =COUNTIF(M_status,"Active") -> 0 | D3: Exited | E3: =COUNTIF(M_status,"Exited") -> 0 | F3: Total records | G3: =COUNTA(M_emp) -> 0 | H3: Active rows with data issues | I3: =COUNTIFS(M_status,"Active",M_issues,">0") -> 0
A4: JOB & EMPLOYMENT | N4: PERSONAL | V4: CONTACT | Z4: ADDRESS | AF4: BANK & STATUTORY | AM4: SALARY (RS / MONTH) | AQ4: AUTO INSIGHTS (DO NOT TYPE) | AW4: HELPER
A5: Sr No | B5: Emp Code | C5: Employee Name | D5: Status | E5: Designation | F5: Department | G5: Location | H5: Employment Type (auto) | I5: DOJ | J5: Exit Date | K5: Exit Reason | L5: Tenure (Yrs) | M5: Reporting To | N5: Father / Husband Name | O5: Gender | P5: Marital Status | Q5: DOB | R5: Age | S5: Blood Group | T5: Aadhaar No | U5: PAN No | V5: Mobile No | W5: Emergency No | X5: Personal Email | Y5: Company Email | Z5: Flat / House No | AA5: Address Line 1 | AB5: Address Line 2 | AC5: City | AD5: State | AE5: Pin Code | AF5: Bank Name | AG5: Account No | AH5: IFSC Code | AI5: Branch | AJ5: ESIC No | AK5: UAN | AL5: PF No | AM5: Previous Salary | AN5: Current Salary | AO5: Last Revision Date | AP5: Hike % | AQ5: Joining FY | AR5: Exit FY | AS5: Days to Birthday | AT5: Days to Work Anniv. | AU5: Data Issues (count) | AV5: Data Issue Details | AW5: bd rank | AX5: an rank
A6: =IF(B6="","",ROW()-5) | D6: =IF(B6="","",IF(J6="","Active","Exited")) | H6: =IF(OR(B6="",I6=""),"",IF(IF(J6="",AsOf,J6)-I6>=Settings!$C$13,"Permanent","Probation")) | L6: =IF(OR(B6="",I6=""),"",ROUND((IF(J6="",AsOf,J6)-I6)/365.25,1)) | R6: =IF(OR(B6="",Q6=""),"",INT((AsOf-Q6)/365.25)) | AP6: =IF(B6="","",IF(AND(ISNUMBER(AM6),ISNUMBER(AN6),AM6>0,AN6>0),AN6/AM6-1,"")) | AQ6: =IF(I6="","",(YEAR(I6)-IF(MONTH(I6)<4,1,0))&"-"&RIGHT((YEAR(I6)-IF(MONTH(I6)<4,1,0))+1,2)) | AR6: =IF(J6="","",(YEAR(J6)-IF(MONTH(J6)<4,1,0))&"-"&RIGHT((YEAR(J6)-IF(MONTH(J6)<4,1,0))+1,2)) | AS6: =IF(OR(B6="",Q6="",D6<>"Active"),"",DATE(YEAR(AsOf)+IF(DATE(YEAR(AsOf),MONTH(Q6),DAY(Q6))<AsOf,1,0),MONTH(Q6),DAY(Q6))-AsOf) | AT6: =IF(OR(B6="",I6="",D6<>"Active"),"",IF(YEAR(DATE(YEAR(AsOf)+IF(DATE(YEAR(AsOf),MONTH(I6),DAY(I6))<AsOf,1,0),MONTH(I6),DAY(I6)))-YEAR(I6)<1,"",DATE(YEAR(AsOf)+IF(DATE(YEAR(AsOf),MONTH(I6),DAY(I6))<AsOf,1,0),MONTH(I6),DAY(I6))-AsOf)) | AU6: =IF(B6="","",IF(AV6="",0,LEN(AV6)-LEN(SUBSTITUTE(AV6,";","")))) | AV6: =IF(B6="","",IF(COUNTIF($B$6:$B$505,B6)>1,"Duplicate Emp Code; ","")&IF(C6="","Name missing; ","")&IF(I6="","DOJ missing; ","")&IF(AND(J6<>"",I6<>"",J6<I6),"Exit before DOJ; ","")&IF(Q6="","DOB missing; ","")&IF(T6="","Aadhaar missing; ",IF(LEN(T6)<>12,"Aadhaar not 12 digits; ",IF(COUNTIF($T$6:$T$505,T6)>1,"Duplicate Aadhaar; ","")))&IF(U6="","PAN missing; ",IF(LEN(U6)<>10,"PAN not 10 chars; ",""))&IF(V6="","Mobile missing; ",IF(LEN(V6)<>10,"Mobile not 10 digits; ",""))&IF(AG6="","Bank A/c missing; ","")&IF(AH6="","IFSC missing; ",IF(LEN(AH6)<>11,"IFSC not 11 chars; ",""))) | AW6: =IF(AS6="","",AS6+ROW()/100000) | AX6: =IF(AT6="","",AT6+ROW()/100000)
A7: =IF(B7="","",ROW()-5) | D7: =IF(B7="","",IF(J7="","Active","Exited")) | H7: =IF(OR(B7="",I7=""),"",IF(IF(J7="",AsOf,J7)-I7>=Settings!$C$13,"Permanent","Probation")) | L7: =IF(OR(B7="",I7=""),"",ROUND((IF(J7="",AsOf,J7)-I7)/365.25,1)) | R7: =IF(OR(B7="",Q7=""),"",INT((AsOf-Q7)/365.25)) | AP7: =IF(B7="","",IF(AND(ISNUMBER(AM7),ISNUMBER(AN7),AM7>0,AN7>0),AN7/AM7-1,"")) | AQ7: =IF(I7="","",(YEAR(I7)-IF(MONTH(I7)<4,1,0))&"-"&RIGHT((YEAR(I7)-IF(MONTH(I7)<4,1,0))+1,2)) | AR7: =IF(J7="","",(YEAR(J7)-IF(MONTH(J7)<4,1,0))&"-"&RIGHT((YEAR(J7)-IF(MONTH(J7)<4,1,0))+1,2)) | AS7: =IF(OR(B7="",Q7="",D7<>"Active"),"",DATE(YEAR(AsOf)+IF(DATE(YEAR(AsOf),MONTH(Q7),DAY(Q7))<AsOf,1,0),MONTH(Q7),DAY(Q7))-AsOf) | AT7: =IF(OR(B7="",I7="",D7<>"Active"),"",IF(YEAR(DATE(YEAR(AsOf)+IF(DATE(YEAR(AsOf),MONTH(I7),DAY(I7))<AsOf,1,0),MONTH(I7),DAY(I7)))-YEAR(I7)<1,"",DATE(YEAR(AsOf)+IF(DATE(YEAR(AsOf),MONTH(I7),DAY(I7))<AsOf,1,0),MONTH(I7),DAY(I7))-AsOf)) | AU7: =IF(B7="","",IF(AV7="",0,LEN(AV7)-LEN(SUBSTITUTE(AV7,";","")))) | AV7: =IF(B7="","",IF(COUNTIF($B$6:$B$505,B7)>1,"Duplicate Emp Code; ","")&IF(C7="","Name missing; ","")&IF(I7="","DOJ missing; ","")&IF(AND(J7<>"",I7<>"",J7<I7),"Exit before DOJ; ","")&IF(Q7="","DOB missing; ","")&IF(T7="","Aadhaar missing; ",IF(LEN(T7)<>12,"Aadhaar not 12 digits; ",IF(COUNTIF($T$6:$T$505,T7)>1,"Duplicate Aadhaar; ","")))&IF(U7="","PAN missing; ",IF(LEN(U7)<>10,"PAN not 10 chars; ",""))&IF(V7="","Mobile missing; ",IF(LEN(V7)<>10,"Mobile not 10 digits; ",""))&IF(AG7="","Bank A/c missing; ","")&IF(AH7="","IFSC missing; ",IF(LEN(AH7)<>11,"IFSC not 11 chars; ",""))) | AW7: =IF(AS7="","",AS7+ROW()/100000) | AX7: =IF(AT7="","",AT7+ROW()/100000)
A8: =IF(B8="","",ROW()-5) | D8: =IF(B8="","",IF(J8="","Active","Exited")) | H8: =IF(OR(B8="",I8=""),"",IF(IF(J8="",AsOf,J8)-I8>=Settings!$C$13,"Permanent","Probation")) | L8: =IF(OR(B8="",I8=""),"",ROUND((IF(J8="",AsOf,J8)-I8)/365.25,1)) | R8: =IF(OR(B8="",Q8=""),"",INT((AsOf-Q8)/365.25)) | AP8: =IF(B8="","",IF(AND(ISNUMBER(AM8),ISNUMBER(AN8),AM8>0,AN8>0),AN8/AM8-1,"")) | AQ8: =IF(I8="","",(YEAR(I8)-IF(MONTH(I8)<4,1,0))&"-"&RIGHT((YEAR(I8)-IF(MONTH(I8)<4,1,0))+1,2)) | AR8: =IF(J8="","",(YEAR(J8)-IF(MONTH(J8)<4,1,0))&"-"&RIGHT((YEAR(J8)-IF(MONTH(J8)<4,1,0))+1,2)) | AS8: =IF(OR(B8="",Q8="",D8<>"Active"),"",DATE(YEAR(AsOf)+IF(DATE(YEAR(AsOf),MONTH(Q8),DAY(Q8))<AsOf,1,0),MONTH(Q8),DAY(Q8))-AsOf) | AT8: =IF(OR(B8="",I8="",D8<>"Active"),"",IF(YEAR(DATE(YEAR(AsOf)+IF(DATE(YEAR(AsOf),MONTH(I8),DAY(I8))<AsOf,1,0),MONTH(I8),DAY(I8)))-YEAR(I8)<1,"",DATE(YEAR(AsOf)+IF(DATE(YEAR(AsOf),MONTH(I8),DAY(I8))<AsOf,1,0),MONTH(I8),DAY(I8))-AsOf)) | AU8: =IF(B8="","",IF(AV8="",0,LEN(AV8)-LEN(SUBSTITUTE(AV8,";","")))) | AV8: =IF(B8="","",IF(COUNTIF($B$6:$B$505,B8)>1,"Duplicate Emp Code; ","")&IF(C8="","Name missing; ","")&IF(I8="","DOJ missing; ","")&IF(AND(J8<>"",I8<>"",J8<I8),"Exit before DOJ; ","")&IF(Q8="","DOB missing; ","")&IF(T8="","Aadhaar missing; ",IF(LEN(T8)<>12,"Aadhaar not 12 digits; ",IF(COUNTIF($T$6:$T$505,T8)>1,"Duplicate Aadhaar; ","")))&IF(U8="","PAN missing; ",IF(LEN(U8)<>10,"PAN not 10 chars; ",""))&IF(V8="","Mobile missing; ",IF(LEN(V8)<>10,"Mobile not 10 digits; ",""))&IF(AG8="","Bank A/c missing; ","")&IF(AH8="","IFSC missing; ",IF(LEN(AH8)<>11,"IFSC not 11 chars; ",""))) | AW8: =IF(AS8="","",AS8+ROW()/100000) | AX8: =IF(AT8="","",AT8+ROW()/100000)
A9: =IF(B9="","",ROW()-5) | D9: =IF(B9="","",IF(J9="","Active","Exited")) | H9: =IF(OR(B9="",I9=""),"",IF(IF(J9="",AsOf,J9)-I9>=Settings!$C$13,"Permanent","Probation")) | L9: =IF(OR(B9="",I9=""),"",ROUND((IF(J9="",AsOf,J9)-I9)/365.25,1)) | R9: =IF(OR(B9="",Q9=""),"",INT((AsOf-Q9)/365.25)) | AP9: =IF(B9="","",IF(AND(ISNUMBER(AM9),ISNUMBER(AN9),AM9>0,AN9>0),AN9/AM9-1,"")) | AQ9: =IF(I9="","",(YEAR(I9)-IF(MONTH(I9)<4,1,0))&"-"&RIGHT((YEAR(I9)-IF(MONTH(I9)<4,1,0))+1,2)) | AR9: =IF(J9="","",(YEAR(J9)-IF(MONTH(J9)<4,1,0))&"-"&RIGHT((YEAR(J9)-IF(MONTH(J9)<4,1,0))+1,2)) | AS9: =IF(OR(B9="",Q9="",D9<>"Active"),"",DATE(YEAR(AsOf)+IF(DATE(YEAR(AsOf),MONTH(Q9),DAY(Q9))<AsOf,1,0),MONTH(Q9),DAY(Q9))-AsOf) | AT9: =IF(OR(B9="",I9="",D9<>"Active"),"",IF(YEAR(DATE(YEAR(AsOf)+IF(DATE(YEAR(AsOf),MONTH(I9),DAY(I9))<AsOf,1,0),MONTH(I9),DAY(I9)))-YEAR(I9)<1,"",DATE(YEAR(AsOf)+IF(DATE(YEAR(AsOf),MONTH(I9),DAY(I9))<AsOf,1,0),MONTH(I9),DAY(I9))-AsOf)) | AU9: =IF(B9="","",IF(AV9="",0,LEN(AV9)-LEN(SUBSTITUTE(AV9,";","")))) | AV9: =IF(B9="","",IF(COUNTIF($B$6:$B$505,B9)>1,"Duplicate Emp Code; ","")&IF(C9="","Name missing; ","")&IF(I9="","DOJ missing; ","")&IF(AND(J9<>"",I9<>"",J9<I9),"Exit before DOJ; ","")&IF(Q9="","DOB missing; ","")&IF(T9="","Aadhaar missing; ",IF(LEN(T9)<>12,"Aadhaar not 12 digits; ",IF(COUNTIF($T$6:$T$505,T9)>1,"Duplicate Aadhaar; ","")))&IF(U9="","PAN missing; ",IF(LEN(U9)<>10,"PAN not 10 chars; ",""))&IF(V9="","Mobile missing; ",IF(LEN(V9)<>10,"Mobile not 10 digits; ",""))&IF(AG9="","Bank A/c missing; ","")&IF(AH9="","IFSC missing; ",IF(LEN(AH9)<>11,"IFSC not 11 chars; ",""))) | AW9: =IF(AS9="","",AS9+ROW()/100000) | AX9: =IF(AT9="","",AT9+ROW()/100000)
A10: =IF(B10="","",ROW()-5) | D10: =IF(B10="","",IF(J10="","Active","Exited")) | H10: =IF(OR(B10="",I10=""),"",IF(IF(J10="",AsOf,J10)-I10>=Settings!$C$13,"Permanent","Probation")) | L10: =IF(OR(B10="",I10=""),"",ROUND((IF(J10="",AsOf,J10)-I10)/365.25,1)) | R10: =IF(OR(B10="",Q10=""),"",INT((AsOf-Q10)/365.25)) | AP10: =IF(B10="","",IF(AND(ISNUMBER(AM10),ISNUMBER(AN10),AM10>0,AN10>0),AN10/AM10-1,"")) | AQ10: =IF(I10="","",(YEAR(I10)-IF(MONTH(I10)<4,1,0))&"-"&RIGHT((YEAR(I10)-IF(MONTH(I10)<4,1,0))+1,2)) | AR10: =IF(J10="","",(YEAR(J10)-IF(MONTH(J10)<4,1,0))&"-"&RIGHT((YEAR(J10)-IF(MONTH(J10)<4,1,0))+1,2)) | AS10: =IF(OR(B10="",Q10="",D10<>"Active"),"",DATE(YEAR(AsOf)+IF(DATE(YEAR(AsOf),MONTH(Q10),DAY(Q10))<AsOf,1,0),MONTH(Q10),DAY(Q10))-AsOf) | AT10: =IF(OR(B10="",I10="",D10<>"Active"),"",IF(YEAR(DATE(YEAR(AsOf)+IF(DATE(YEAR(AsOf),MONTH(I10),DAY(I10))<AsOf,1,0),MONTH(I10),DAY(I10)))-YEAR(I10)<1,"",DATE(YEAR(AsOf)+IF(DATE(YEAR(AsOf),MONTH(I10),DAY(I10))<AsOf,1,0),MONTH(I10),DAY(I10))-AsOf)) | AU10: =IF(B10="","",IF(AV10="",0,LEN(AV10)-LEN(SUBSTITUTE(AV10,";","")))) | AV10: =IF(B10="","",IF(COUNTIF($B$6:$B$505,B10)>1,"Duplicate Emp Code; ","")&IF(C10="","Name missing; ","")&IF(I10="","DOJ missing; ","")&IF(AND(J10<>"",I10<>"",J10<I10),"Exit before DOJ; ","")&IF(Q10="","DOB missing; ","")&IF(T10="","Aadhaar missing; ",IF(LEN(T10)<>12,"Aadhaar not 12 digits; ",IF(COUNTIF($T$6:$T$505,T10)>1,"Duplicate Aadhaar; ","")))&IF(U10="","PAN missing; ",IF(LEN(U10)<>10,"PAN not 10 chars; ",""))&IF(V10="","Mobile missing; ",IF(LEN(V10)<>10,"Mobile not 10 digits; ",""))&IF(AG10="","Bank A/c missing; ","")&IF(AH10="","IFSC missing; ",IF(LEN(AH10)<>11,"IFSC not 11 chars; ",""))) | AW10: =IF(AS10="","",AS10+ROW()/100000) | AX10: =IF(AT10="","",AT10+ROW()/100000)
A11: =IF(B11="","",ROW()-5) | D11: =IF(B11="","",IF(J11="","Active","Exited")) | H11: =IF(OR(B11="",I11=""),"",IF(IF(J11="",AsOf,J11)-I11>=Settings!$C$13,"Permanent","Probation")) | L11: =IF(OR(B11="",I11=""),"",ROUND((IF(J11="",AsOf,J11)-I11)/365.25,1)) | R11: =IF(OR(B11="",Q11=""),"",INT((AsOf-Q11)/365.25)) | AP11: =IF(B11="","",IF(AND(ISNUMBER(AM11),ISNUMBER(AN11),AM11>0,AN11>0),AN11/AM11-1,"")) | AQ11: =IF(I11="","",(YEAR(I11)-IF(MONTH(I11)<4,1,0))&"-"&RIGHT((YEAR(I11)-IF(MONTH(I11)<4,1,0))+1,2)) | AR11: =IF(J11="","",(YEAR(J11)-IF(MONTH(J11)<4,1,0))&"-"&RIGHT((YEAR(J11)-IF(MONTH(J11)<4,1,0))+1,2)) | AS11: =IF(OR(B11="",Q11="",D11<>"Active"),"",DATE(YEAR(AsOf)+IF(DATE(YEAR(AsOf),MONTH(Q11),DAY(Q11))<AsOf,1,0),MONTH(Q11),DAY(Q11))-AsOf) | AT11: =IF(OR(B11="",I11="",D11<>"Active"),"",IF(YEAR(DATE(YEAR(AsOf)+IF(DATE(YEAR(AsOf),MONTH(I11),DAY(I11))<AsOf,1,0),MONTH(I11),DAY(I11)))-YEAR(I11)<1,"",DATE(YEAR(AsOf)+IF(DATE(YEAR(AsOf),MONTH(I11),DAY(I11))<AsOf,1,0),MONTH(I11),DAY(I11))-AsOf)) | AU11: =IF(B11="","",IF(AV11="",0,LEN(AV11)-LEN(SUBSTITUTE(AV11,";","")))) | AV11: =IF(B11="","",IF(COUNTIF($B$6:$B$505,B11)>1,"Duplicate Emp Code; ","")&IF(C11="","Name missing; ","")&IF(I11="","DOJ missing; ","")&IF(AND(J11<>"",I11<>"",J11<I11),"Exit before DOJ; ","")&IF(Q11="","DOB missing; ","")&IF(T11="","Aadhaar missing; ",IF(LEN(T11)<>12,"Aadhaar not 12 digits; ",IF(COUNTIF($T$6:$T$505,T11)>1,"Duplicate Aadhaar; ","")))&IF(U11="","PAN missing; ",IF(LEN(U11)<>10,"PAN not 10 chars; ",""))&IF(V11="","Mobile missing; ",IF(LEN(V11)<>10,"Mobile not 10 digits; ",""))&IF(AG11="","Bank A/c missing; ","")&IF(AH11="","IFSC missing; ",IF(LEN(AH11)<>11,"IFSC not 11 chars; ",""))) | AW11: =IF(AS11="","",AS11+ROW()/100000) | AX11: =IF(AT11="","",AT11+ROW()/100000)
A12: =IF(B12="","",ROW()-5) | D12: =IF(B12="","",IF(J12="","Active","Exited")) | H12: =IF(OR(B12="",I12=""),"",IF(IF(J12="",AsOf,J12)-I12>=Settings!$C$13,"Permanent","Probation")) | L12: =IF(OR(B12="",I12=""),"",ROUND((IF(J12="",AsOf,J12)-I12)/365.25,1)) | R12: =IF(OR(B12="",Q12=""),"",INT((AsOf-Q12)/365.25)) | AP12: =IF(B12="","",IF(AND(ISNUMBER(AM12),ISNUMBER(AN12),AM12>0,AN12>0),AN12/AM12-1,"")) | AQ12: =IF(I12="","",(YEAR(I12)-IF(MONTH(I12)<4,1,0))&"-"&RIGHT((YEAR(I12)-IF(MONTH(I12)<4,1,0))+1,2)) | AR12: =IF(J12="","",(YEAR(J12)-IF(MONTH(J12)<4,1,0))&"-"&RIGHT((YEAR(J12)-IF(MONTH(J12)<4,1,0))+1,2)) | AS12: =IF(OR(B12="",Q12="",D12<>"Active"),"",DATE(YEAR(AsOf)+IF(DATE(YEAR(AsOf),MONTH(Q12),DAY(Q12))<AsOf,1,0),MONTH(Q12),DAY(Q12))-AsOf) | AT12: =IF(OR(B12="",I12="",D12<>"Active"),"",IF(YEAR(DATE(YEAR(AsOf)+IF(DATE(YEAR(AsOf),MONTH(I12),DAY(I12))<AsOf,1,0),MONTH(I12),DAY(I12)))-YEAR(I12)<1,"",DATE(YEAR(AsOf)+IF(DATE(YEAR(AsOf),MONTH(I12),DAY(I12))<AsOf,1,0),MONTH(I12),DAY(I12))-AsOf)) | AU12: =IF(B12="","",IF(AV12="",0,LEN(AV12)-LEN(SUBSTITUTE(AV12,";","")))) | AV12: =IF(B12="","",IF(COUNTIF($B$6:$B$505,B12)>1,"Duplicate Emp Code; ","")&IF(C12="","Name missing; ","")&IF(I12="","DOJ missing; ","")&IF(AND(J12<>"",I12<>"",J12<I12),"Exit before DOJ; ","")&IF(Q12="","DOB missing; ","")&IF(T12="","Aadhaar missing; ",IF(LEN(T12)<>12,"Aadhaar not 12 digits; ",IF(COUNTIF($T$6:$T$505,T12)>1,"Duplicate Aadhaar; ","")))&IF(U12="","PAN missing; ",IF(LEN(U12)<>10,"PAN not 10 chars; ",""))&IF(V12="","Mobile missing; ",IF(LEN(V12)<>10,"Mobile not 10 digits; ",""))&IF(AG12="","Bank A/c missing; ","")&IF(AH12="","IFSC missing; ",IF(LEN(AH12)<>11,"IFSC not 11 chars; ",""))) | AW12: =IF(AS12="","",AS12+ROW()/100000) | AX12: =IF(AT12="","",AT12+ROW()/100000)
A13: =IF(B13="","",ROW()-5) | D13: =IF(B13="","",IF(J13="","Active","Exited")) | H13: =IF(OR(B13="",I13=""),"",IF(IF(J13="",AsOf,J13)-I13>=Settings!$C$13,"Permanent","Probation")) | L13: =IF(OR(B13="",I13=""),"",ROUND((IF(J13="",AsOf,J13)-I13)/365.25,1)) | R13: =IF(OR(B13="",Q13=""),"",INT((AsOf-Q13)/365.25)) | AP13: =IF(B13="","",IF(AND(ISNUMBER(AM13),ISNUMBER(AN13),AM13>0,AN13>0),AN13/AM13-1,"")) | AQ13: =IF(I13="","",(YEAR(I13)-IF(MONTH(I13)<4,1,0))&"-"&RIGHT((YEAR(I13)-IF(MONTH(I13)<4,1,0))+1,2)) | AR13: =IF(J13="","",(YEAR(J13)-IF(MONTH(J13)<4,1,0))&"-"&RIGHT((YEAR(J13)-IF(MONTH(J13)<4,1,0))+1,2)) | AS13: =IF(OR(B13="",Q13="",D13<>"Active"),"",DATE(YEAR(AsOf)+IF(DATE(YEAR(AsOf),MONTH(Q13),DAY(Q13))<AsOf,1,0),MONTH(Q13),DAY(Q13))-AsOf) | AT13: =IF(OR(B13="",I13="",D13<>"Active"),"",IF(YEAR(DATE(YEAR(AsOf)+IF(DATE(YEAR(AsOf),MONTH(I13),DAY(I13))<AsOf,1,0),MONTH(I13),DAY(I13)))-YEAR(I13)<1,"",DATE(YEAR(AsOf)+IF(DATE(YEAR(AsOf),MONTH(I13),DAY(I13))<AsOf,1,0),MONTH(I13),DAY(I13))-AsOf)) | AU13: =IF(B13="","",IF(AV13="",0,LEN(AV13)-LEN(SUBSTITUTE(AV13,";","")))) | AV13: =IF(B13="","",IF(COUNTIF($B$6:$B$505,B13)>1,"Duplicate Emp Code; ","")&IF(C13="","Name missing; ","")&IF(I13="","DOJ missing; ","")&IF(AND(J13<>"",I13<>"",J13<I13),"Exit before DOJ; ","")&IF(Q13="","DOB missing; ","")&IF(T13="","Aadhaar missing; ",IF(LEN(T13)<>12,"Aadhaar not 12 digits; ",IF(COUNTIF($T$6:$T$505,T13)>1,"Duplicate Aadhaar; ","")))&IF(U13="","PAN missing; ",IF(LEN(U13)<>10,"PAN not 10 chars; ",""))&IF(V13="","Mobile missing; ",IF(LEN(V13)<>10,"Mobile not 10 digits; ",""))&IF(AG13="","Bank A/c missing; ","")&IF(AH13="","IFSC missing; ",IF(LEN(AH13)<>11,"IFSC not 11 chars; ",""))) | AW13: =IF(AS13="","",AS13+ROW()/100000) | AX13: =IF(AT13="","",AT13+ROW()/100000)
A14: =IF(B14="","",ROW()-5) | D14: =IF(B14="","",IF(J14="","Active","Exited")) | H14: =IF(OR(B14="",I14=""),"",IF(IF(J14="",AsOf,J14)-I14>=Settings!$C$13,"Permanent","Probation")) | L14: =IF(OR(B14="",I14=""),"",ROUND((IF(J14="",AsOf,J14)-I14)/365.25,1)) | R14: =IF(OR(B14="",Q14=""),"",INT((AsOf-Q14)/365.25)) | AP14: =IF(B14="","",IF(AND(ISNUMBER(AM14),ISNUMBER(AN14),AM14>0,AN14>0),AN14/AM14-1,"")) | AQ14: =IF(I14="","",(YEAR(I14)-IF(MONTH(I14)<4,1,0))&"-"&RIGHT((YEAR(I14)-IF(MONTH(I14)<4,1,0))+1,2)) | AR14: =IF(J14="","",(YEAR(J14)-IF(MONTH(J14)<4,1,0))&"-"&RIGHT((YEAR(J14)-IF(MONTH(J14)<4,1,0))+1,2)) | AS14: =IF(OR(B14="",Q14="",D14<>"Active"),"",DATE(YEAR(AsOf)+IF(DATE(YEAR(AsOf),MONTH(Q14),DAY(Q14))<AsOf,1,0),MONTH(Q14),DAY(Q14))-AsOf) | AT14: =IF(OR(B14="",I14="",D14<>"Active"),"",IF(YEAR(DATE(YEAR(AsOf)+IF(DATE(YEAR(AsOf),MONTH(I14),DAY(I14))<AsOf,1,0),MONTH(I14),DAY(I14)))-YEAR(I14)<1,"",DATE(YEAR(AsOf)+IF(DATE(YEAR(AsOf),MONTH(I14),DAY(I14))<AsOf,1,0),MONTH(I14),DAY(I14))-AsOf)) | AU14: =IF(B14="","",IF(AV14="",0,LEN(AV14)-LEN(SUBSTITUTE(AV14,";","")))) | AV14: =IF(B14="","",IF(COUNTIF($B$6:$B$505,B14)>1,"Duplicate Emp Code; ","")&IF(C14="","Name missing; ","")&IF(I14="","DOJ missing; ","")&IF(AND(J14<>"",I14<>"",J14<I14),"Exit before DOJ; ","")&IF(Q14="","DOB missing; ","")&IF(T14="","Aadhaar missing; ",IF(LEN(T14)<>12,"Aadhaar not 12 digits; ",IF(COUNTIF($T$6:$T$505,T14)>1,"Duplicate Aadhaar; ","")))&IF(U14="","PAN missing; ",IF(LEN(U14)<>10,"PAN not 10 chars; ",""))&IF(V14="","Mobile missing; ",IF(LEN(V14)<>10,"Mobile not 10 digits; ",""))&IF(AG14="","Bank A/c missing; ","")&IF(AH14="","IFSC missing; ",IF(LEN(AH14)<>11,"IFSC not 11 chars; ",""))) | AW14: =IF(AS14="","",AS14+ROW()/100000) | AX14: =IF(AT14="","",AT14+ROW()/100000)
A15: =IF(B15="","",ROW()-5) | D15: =IF(B15="","",IF(J15="","Active","Exited")) | H15: =IF(OR(B15="",I15=""),"",IF(IF(J15="",AsOf,J15)-I15>=Settings!$C$13,"Permanent","Probation")) | L15: =IF(OR(B15="",I15=""),"",ROUND((IF(J15="",AsOf,J15)-I15)/365.25,1)) | R15: =IF(OR(B15="",Q15=""),"",INT((AsOf-Q15)/365.25)) | AP15: =IF(B15="","",IF(AND(ISNUMBER(AM15),ISNUMBER(AN15),AM15>0,AN15>0),AN15/AM15-1,"")) | AQ15: =IF(I15="","",(YEAR(I15)-IF(MONTH(I15)<4,1,0))&"-"&RIGHT((YEAR(I15)-IF(MONTH(I15)<4,1,0))+1,2)) | AR15: =IF(J15="","",(YEAR(J15)-IF(MONTH(J15)<4,1,0))&"-"&RIGHT((YEAR(J15)-IF(MONTH(J15)<4,1,0))+1,2)) | AS15: =IF(OR(B15="",Q15="",D15<>"Active"),"",DATE(YEAR(AsOf)+IF(DATE(YEAR(AsOf),MONTH(Q15),DAY(Q15))<AsOf,1,0),MONTH(Q15),DAY(Q15))-AsOf) | AT15: =IF(OR(B15="",I15="",D15<>"Active"),"",IF(YEAR(DATE(YEAR(AsOf)+IF(DATE(YEAR(AsOf),MONTH(I15),DAY(I15))<AsOf,1,0),MONTH(I15),DAY(I15)))-YEAR(I15)<1,"",DATE(YEAR(AsOf)+IF(DATE(YEAR(AsOf),MONTH(I15),DAY(I15))<AsOf,1,0),MONTH(I15),DAY(I15))-AsOf)) | AU15: =IF(B15="","",IF(AV15="",0,LEN(AV15)-LEN(SUBSTITUTE(AV15,";","")))) | AV15: =IF(B15="","",IF(COUNTIF($B$6:$B$505,B15)>1,"Duplicate Emp Code; ","")&IF(C15="","Name missing; ","")&IF(I15="","DOJ missing; ","")&IF(AND(J15<>"",I15<>"",J15<I15),"Exit before DOJ; ","")&IF(Q15="","DOB missing; ","")&IF(T15="","Aadhaar missing; ",IF(LEN(T15)<>12,"Aadhaar not 12 digits; ",IF(COUNTIF($T$6:$T$505,T15)>1,"Duplicate Aadhaar; ","")))&IF(U15="","PAN missing; ",IF(LEN(U15)<>10,"PAN not 10 chars; ",""))&IF(V15="","Mobile missing; ",IF(LEN(V15)<>10,"Mobile not 10 digits; ",""))&IF(AG15="","Bank A/c missing; ","")&IF(AH15="","IFSC missing; ",IF(LEN(AH15)<>11,"IFSC not 11 chars; ",""))) | AW15: =IF(AS15="","",AS15+ROW()/100000) | AX15: =IF(AT15="","",AT15+ROW()/100000)
A16: =IF(B16="","",ROW()-5) | D16: =IF(B16="","",IF(J16="","Active","Exited")) | H16: =IF(OR(B16="",I16=""),"",IF(IF(J16="",AsOf,J16)-I16>=Settings!$C$13,"Permanent","Probation")) | L16: =IF(OR(B16="",I16=""),"",ROUND((IF(J16="",AsOf,J16)-I16)/365.25,1)) | R16: =IF(OR(B16="",Q16=""),"",INT((AsOf-Q16)/365.25)) | AP16: =IF(B16="","",IF(AND(ISNUMBER(AM16),ISNUMBER(AN16),AM16>0,AN16>0),AN16/AM16-1,"")) | AQ16: =IF(I16="","",(YEAR(I16)-IF(MONTH(I16)<4,1,0))&"-"&RIGHT((YEAR(I16)-IF(MONTH(I16)<4,1,0))+1,2)) | AR16: =IF(J16="","",(YEAR(J16)-IF(MONTH(J16)<4,1,0))&"-"&RIGHT((YEAR(J16)-IF(MONTH(J16)<4,1,0))+1,2)) | AS16: =IF(OR(B16="",Q16="",D16<>"Active"),"",DATE(YEAR(AsOf)+IF(DATE(YEAR(AsOf),MONTH(Q16),DAY(Q16))<AsOf,1,0),MONTH(Q16),DAY(Q16))-AsOf) | AT16: =IF(OR(B16="",I16="",D16<>"Active"),"",IF(YEAR(DATE(YEAR(AsOf)+IF(DATE(YEAR(AsOf),MONTH(I16),DAY(I16))<AsOf,1,0),MONTH(I16),DAY(I16)))-YEAR(I16)<1,"",DATE(YEAR(AsOf)+IF(DATE(YEAR(AsOf),MONTH(I16),DAY(I16))<AsOf,1,0),MONTH(I16),DAY(I16))-AsOf)) | AU16: =IF(B16="","",IF(AV16="",0,LEN(AV16)-LEN(SUBSTITUTE(AV16,";","")))) | AV16: =IF(B16="","",IF(COUNTIF($B$6:$B$505,B16)>1,"Duplicate Emp Code; ","")&IF(C16="","Name missing; ","")&IF(I16="","DOJ missing; ","")&IF(AND(J16<>"",I16<>"",J16<I16),"Exit before DOJ; ","")&IF(Q16="","DOB missing; ","")&IF(T16="","Aadhaar missing; ",IF(LEN(T16)<>12,"Aadhaar not 12 digits; ",IF(COUNTIF($T$6:$T$505,T16)>1,"Duplicate Aadhaar; ","")))&IF(U16="","PAN missing; ",IF(LEN(U16)<>10,"PAN not 10 chars; ",""))&IF(V16="","Mobile missing; ",IF(LEN(V16)<>10,"Mobile not 10 digits; ",""))&IF(AG16="","Bank A/c missing; ","")&IF(AH16="","IFSC missing; ",IF(LEN(AH16)<>11,"IFSC not 11 chars; ",""))) | AW16: =IF(AS16="","",AS16+ROW()/100000) | AX16: =IF(AT16="","",AT16+ROW()/100000)
A17: =IF(B17="","",ROW()-5) | D17: =IF(B17="","",IF(J17="","Active","Exited")) | H17: =IF(OR(B17="",I17=""),"",IF(IF(J17="",AsOf,J17)-I17>=Settings!$C$13,"Permanent","Probation")) | L17: =IF(OR(B17="",I17=""),"",ROUND((IF(J17="",AsOf,J17)-I17)/365.25,1)) | R17: =IF(OR(B17="",Q17=""),"",INT((AsOf-Q17)/365.25)) | AP17: =IF(B17="","",IF(AND(ISNUMBER(AM17),ISNUMBER(AN17),AM17>0,AN17>0),AN17/AM17-1,"")) | AQ17: =IF(I17="","",(YEAR(I17)-IF(MONTH(I17)<4,1,0))&"-"&RIGHT((YEAR(I17)-IF(MONTH(I17)<4,1,0))+1,2)) | AR17: =IF(J17="","",(YEAR(J17)-IF(MONTH(J17)<4,1,0))&"-"&RIGHT((YEAR(J17)-IF(MONTH(J17)<4,1,0))+1,2)) | AS17: =IF(OR(B17="",Q17="",D17<>"Active"),"",DATE(YEAR(AsOf)+IF(DATE(YEAR(AsOf),MONTH(Q17),DAY(Q17))<AsOf,1,0),MONTH(Q17),DAY(Q17))-AsOf) | AT17: =IF(OR(B17="",I17="",D17<>"Active"),"",IF(YEAR(DATE(YEAR(AsOf)+IF(DATE(YEAR(AsOf),MONTH(I17),DAY(I17))<AsOf,1,0),MONTH(I17),DAY(I17)))-YEAR(I17)<1,"",DATE(YEAR(AsOf)+IF(DATE(YEAR(AsOf),MONTH(I17),DAY(I17))<AsOf,1,0),MONTH(I17),DAY(I17))-AsOf)) | AU17: =IF(B17="","",IF(AV17="",0,LEN(AV17)-LEN(SUBSTITUTE(AV17,";","")))) | AV17: =IF(B17="","",IF(COUNTIF($B$6:$B$505,B17)>1,"Duplicate Emp Code; ","")&IF(C17="","Name missing; ","")&IF(I17="","DOJ missing; ","")&IF(AND(J17<>"",I17<>"",J17<I17),"Exit before DOJ; ","")&IF(Q17="","DOB missing; ","")&IF(T17="","Aadhaar missing; ",IF(LEN(T17)<>12,"Aadhaar not 12 digits; ",IF(COUNTIF($T$6:$T$505,T17)>1,"Duplicate Aadhaar; ","")))&IF(U17="","PAN missing; ",IF(LEN(U17)<>10,"PAN not 10 chars; ",""))&IF(V17="","Mobile missing; ",IF(LEN(V17)<>10,"Mobile not 10 digits; ",""))&IF(AG17="","Bank A/c missing; ","")&IF(AH17="","IFSC missing; ",IF(LEN(AH17)<>11,"IFSC not 11 chars; ",""))) | AW17: =IF(AS17="","",AS17+ROW()/100000) | AX17: =IF(AT17="","",AT17+ROW()/100000)
... A505: =IF(B505="","",ROW()-5) | D505: =IF(B505="","",IF(J505="","Active","Exited")) | H505: =IF(OR(B505="",I505=""),"",IF(IF(J505="",AsOf,J505)-I505>=Settings!$C$13,"Permanent","Probation")) | L505: =IF(OR(B505="",I505=""),"",ROUND((IF(J505="",AsOf,J505)-I505)/365.25,1)) | R505: =IF(OR(B505="",Q505=""),"",INT((AsOf-Q505)/365.25)) | AP505: =IF(B505="","",IF(AND(ISNUMBER(AM505),ISNUMBER(AN505),AM505>0,AN505>0),AN505/AM505-1,"")) | AQ505: =IF(I505="","",(YEAR(I505)-IF(MONTH(I505)<4,1,0))&"-"&RIGHT((YEAR(I505)-IF(MONTH(I505)<4,1,0))+1,2)) | AR505: =IF(J505="","",(YEAR(J505)-IF(MONTH(J505)<4,1,0))&"-"&RIGHT((YEAR(J505)-IF(MONTH(J505)<4,1,0))+1,2)) | AS505: =IF(OR(B505="",Q505="",D505<>"Active"),"",DATE(YEAR(AsOf)+IF(DATE(YEAR(AsOf),MONTH(Q505),DAY(Q505))<AsOf,1,0),MONTH(Q505),DAY(Q505))-AsOf) | AT505: =IF(OR(B505="",I505="",D505<>"Active"),"",IF(YEAR(DATE(YEAR(AsOf)+IF(DATE(YEAR(AsOf),MONTH(I505),DAY(I505))<AsOf,1,0),MONTH(I505),DAY(I505)))-YEAR(I505)<1,"",DATE(YEAR(AsOf)+IF(DATE(YEAR(AsOf),MONTH(I505),DAY(I505))<AsOf,1,0),MONTH(I505),DAY(I505))-AsOf)) | AU505: =IF(B505="","",IF(AV505="",0,LEN(AV505)-LEN(SUBSTITUTE(AV505,";","")))) | AV505: =IF(B505="","",IF(COUNTIF($B$6:$B$505,B505)>1,"Duplicate Emp Code; ","")&IF(C505="","Name missing; ","")&IF(I505="","DOJ missing; ","")&IF(AND(J505<>"",I505<>"",J505<I505),"Exit before DOJ; ","")&IF(Q505="","DOB missing; ","")&IF(T505="","Aadhaar missing; ",IF(LEN(T505)<>12,"Aadhaar not 12 digits; ",IF(COUNTIF($T$6:$T$505,T505)>1,"Duplicate Aadhaar; ","")))&IF(U505="","PAN missing; ",IF(LEN(U505)<>10,"PAN not 10 chars; ",""))&IF(V505="","Mobile missing; ",IF(LEN(V505)<>10,"Mobile not 10 digits; ",""))&IF(AG505="","Bank A/c missing; ","")&IF(AH505="","IFSC missing; ",IF(LEN(AH505)<>11,"IFSC not 11 chars; ",""))) | AW505: =IF(AS505="","",AS505+ROW()/100000) | AX505: =IF(AT505="","",AT505+ROW()/100000)

Sheet Employee Card
B1: EMPLOYEE CARD
H2: row #
B3: Select Emp Code > | E3: (pick from the dropdown or type a code) | H3: =IFERROR(MATCH(C3,M_emp,0),"")
B5: =IF($H$3="","",INDEX(M_name,$H$3))
B6: =IF($H$3="","",INDEX(M_pos,$H$3)&" | "&INDEX(M_dept,$H$3)&" | "&INDEX(M_loc,$H$3)&" | "&INDEX(M_status,$H$3))
B8: JOB DETAILS | E8: CONTACT | H8: SALARY (Rs / month)
B9: Emp Code | C9: =IF($H$3="","",IFERROR(IF(INDEX(M_emp,$H$3)="","",INDEX(M_emp,$H$3)),"")) | E9: Mobile No | F9: =IF($H$3="","",IFERROR(IF(INDEX(M_mobile,$H$3)="","",INDEX(M_mobile,$H$3)),"")) | H9: Current Salary | I9: =IF($H$3="","",IFERROR(IF(INDEX(M_sal,$H$3)="","",INDEX(M_sal,$H$3)),""))
B10: Designation | C10: =IF($H$3="","",IFERROR(IF(INDEX(M_pos,$H$3)="","",INDEX(M_pos,$H$3)),"")) | E10: Emergency No | F10: =IF($H$3="","",IFERROR(IF(INDEX(M_emerg,$H$3)="","",INDEX(M_emerg,$H$3)),"")) | H10: Previous Salary | I10: =IF($H$3="","",IFERROR(IF(INDEX(M_prevsal,$H$3)="","",INDEX(M_prevsal,$H$3)),""))
B11: Department | C11: =IF($H$3="","",IFERROR(IF(INDEX(M_dept,$H$3)="","",INDEX(M_dept,$H$3)),"")) | E11: Personal Email | F11: =IF($H$3="","",IFERROR(IF(INDEX(M_pemail,$H$3)="","",INDEX(M_pemail,$H$3)),"")) | H11: Last Revision | I11: =IF($H$3="","",IFERROR(IF(INDEX(M_revdate,$H$3)="","",INDEX(M_revdate,$H$3)),""))
B12: Location | C12: =IF($H$3="","",IFERROR(IF(INDEX(M_loc,$H$3)="","",INDEX(M_loc,$H$3)),"")) | E12: Company Email | F12: =IF($H$3="","",IFERROR(IF(INDEX(M_cemail,$H$3)="","",INDEX(M_cemail,$H$3)),"")) | H12: Hike % | I12: =IF($H$3="","",IFERROR(IF(INDEX(M_hike,$H$3)="","",INDEX(M_hike,$H$3)),""))
B13: Employment Type | C13: =IF($H$3="","",IFERROR(IF(INDEX(M_type,$H$3)="","",INDEX(M_type,$H$3)),""))
B14: Status | C14: =IF($H$3="","",IFERROR(IF(INDEX(M_status,$H$3)="","",INDEX(M_status,$H$3)),"")) | E14: ADDRESS
B15: Date of Joining | C15: =IF($H$3="","",IFERROR(IF(INDEX(M_doj,$H$3)="","",INDEX(M_doj,$H$3)),"")) | E15: Flat / House No | F15: =IF($H$3="","",IFERROR(IF(INDEX(M_addr0,$H$3)="","",INDEX(M_addr0,$H$3)),""))
B16: Exit Date | C16: =IF($H$3="","",IFERROR(IF(INDEX(M_exit,$H$3)="","",INDEX(M_exit,$H$3)),"")) | E16: Address Line 1 | F16: =IF($H$3="","",IFERROR(IF(INDEX(M_addr1,$H$3)="","",INDEX(M_addr1,$H$3)),""))
B17: Exit Reason | C17: =IF($H$3="","",IFERROR(IF(INDEX(M_exitreason,$H$3)="","",INDEX(M_exitreason,$H$3)),"")) | E17: Address Line 2 | F17: =IF($H$3="","",IFERROR(IF(INDEX(M_addr2,$H$3)="","",INDEX(M_addr2,$H$3)),""))
B18: Tenure (yrs) | C18: =IF($H$3="","",IFERROR(IF(INDEX(M_ten,$H$3)="","",INDEX(M_ten,$H$3)),"")) | E18: City | F18: =IF($H$3="","",IFERROR(IF(INDEX(M_city,$H$3)="","",INDEX(M_city,$H$3)),""))
B19: Reporting To | C19: =IF($H$3="","",IFERROR(IF(INDEX(M_report,$H$3)="","",INDEX(M_report,$H$3)),"")) | E19: State | F19: =IF($H$3="","",IFERROR(IF(INDEX(M_state,$H$3)="","",INDEX(M_state,$H$3)),""))
E20: Pin Code | F20: =IF($H$3="","",IFERROR(IF(INDEX(M_pin,$H$3)="","",INDEX(M_pin,$H$3)),""))
B21: PERSONAL
B22: Father / Husband | C22: =IF($H$3="","",IFERROR(IF(INDEX(M_fname,$H$3)="","",INDEX(M_fname,$H$3)),"")) | E22: BANK & STATUTORY
B23: Gender | C23: =IF($H$3="","",IFERROR(IF(INDEX(M_sex,$H$3)="","",INDEX(M_sex,$H$3)),"")) | E23: Bank | F23: =IF($H$3="","",IFERROR(IF(INDEX(M_bank,$H$3)="","",INDEX(M_bank,$H$3)),""))
B24: Marital Status | C24: =IF($H$3="","",IFERROR(IF(INDEX(M_mar,$H$3)="","",INDEX(M_mar,$H$3)),"")) | E24: Account No | F24: =IF($H$3="","",IFERROR(IF(INDEX(M_acct,$H$3)="","",INDEX(M_acct,$H$3)),""))
B25: Date of Birth | C25: =IF($H$3="","",IFERROR(IF(INDEX(M_dob,$H$3)="","",INDEX(M_dob,$H$3)),"")) | E25: IFSC | F25: =IF($H$3="","",IFERROR(IF(INDEX(M_ifsc,$H$3)="","",INDEX(M_ifsc,$H$3)),""))
B26: Age | C26: =IF($H$3="","",IFERROR(IF(INDEX(M_age,$H$3)="","",INDEX(M_age,$H$3)),"")) | E26: Branch | F26: =IF($H$3="","",IFERROR(IF(INDEX(M_branch,$H$3)="","",INDEX(M_branch,$H$3)),""))
B27: Blood Group | C27: =IF($H$3="","",IFERROR(IF(INDEX(M_blood,$H$3)="","",INDEX(M_blood,$H$3)),"")) | E27: ESIC No | F27: =IF($H$3="","",IFERROR(IF(INDEX(M_esic,$H$3)="","",INDEX(M_esic,$H$3)),""))
B28: Aadhaar No | C28: =IF($H$3="","",IFERROR(IF(INDEX(M_aadhaar,$H$3)="","",INDEX(M_aadhaar,$H$3)),"")) | E28: UAN | F28: =IF($H$3="","",IFERROR(IF(INDEX(M_uan,$H$3)="","",INDEX(M_uan,$H$3)),""))
B29: PAN No | C29: =IF($H$3="","",IFERROR(IF(INDEX(M_pan,$H$3)="","",INDEX(M_pan,$H$3)),"")) | E29: PF No | F29: =IF($H$3="","",IFERROR(IF(INDEX(M_pf,$H$3)="","",INDEX(M_pf,$H$3)),""))

Sheet Settings
B1: Settings & Legend
B2: Yellow cells with blue text are inputs - edit them and every sheet recalculates.
B4: Setting | C4: Value | D4: Note
B5: Company name | C5: Your Company Name | D5: Appears in the titles of every sheet.
B6: Report / As-of date | C6: =TODAY() -> 46322 | D6: Auto = today. Type a fixed date to freeze age / tenure / birthday calculations.
B7: Leave year | C7: =YEAR(C6) -> 2026 | D7: Auto = year of the report date. Type a year (e.g. 2026) to fix it. Carry-forward PL is entered in Leave Record.
B8: Current financial year (auto) | C8: =IF(MONTH(C6)>=4,YEAR(C6),YEAR(C6)-1)&"-"&RIGHT(IF(MONTH(C6)>=4,YEAR(C6),YEAR(C6)-1)+1,2) -> 2026-27 | D8: Apr-Mar. Used for joiners / exits this FY.
B9: Leave as-of date (auto) | C9: =MIN(C6,DATE(C7,12,31)) -> 46322 | D9: Report date capped at the leave-year end.
B10: CL (Casual Leave) per year | C10: 7 | D10: Default from your Leave Tracker template.
B11: SL (Sick Leave) per year | C11: 7 | D11: Default from your Leave Tracker template.
B12: PL (Paid Leave) per year | C12: 18 | D12: Accrued pro-rata: PL/365 per day from the eligibility date (rounded down to 0.5).
B13: Confirmation period (days after DOJ) | C13: 90 | D13: Employment Type: Permanent once an employee is this many days past DOJ, otherwise Probation.
B14: Training days per year (per employee) | C14: 0 | D14: ASSUMPTION: set to your training policy (0 = none).
B15: "LOW" alert when total pending (CL+SL+PL) is at or below | C15: 3 | D15: Flags employees on the Dashboard attention list.
B16: Free late marks per month before deduction | C16: 3 | D16: Default from your Leave Tracker template.
B17: Deduction per extra late mark (days) | C17: 0.5 | D17: Default from your Leave Tracker template.
B18: Birthday / anniversary alert window (days) | C18: 30 | D18: Dashboard counts birthdays and work anniversaries within this many days.
B21: Attendance codes (type or pick from the dropdown in the day cells of the Attendance sheet)
B22: Code | C22: Meaning | D22: Effect on payable days / leave balance
B23: P | C23: Present | D23: 1 payable day
B24: A | C24: Absent | D24: Not paid
B25: HA | C25: Half-day absent | D25: 0.5 payable day
B26: L | C26: Late | D26: 1 payable day; counts toward late deduction
B27: PL | C27: Paid Leave | D27: 1 payable day; 1 deducted from PL balance
B28: HPL | C28: Half-day Paid Leave | D28: 1 payable day (0.5 leave + 0.5 worked); 0.5 deducted from PL balance
B29: CL | C29: Casual Leave | D29: 1 payable day; 1 deducted from CL balance
B30: HCL | C30: Half-day Casual Leave | D30: 1 payable day (0.5 leave + 0.5 worked); 0.5 deducted from CL balance
B31: SL | C31: Sick Leave | D31: 1 payable day; 1 deducted from SL balance
B32: CO | C32: Compensatory Off | D32: 1 payable day
B33: WO | C33: Weekly Off | D33: 1 payable day
... B35: TR | C35: Training Day | D35: 1 payable day; counted against Training days balance
B37: Note: half-day codes (HA, HPL, HCL) are treated as shown above. If your payroll rule is different, edit the Gross Payable Days formula in Attendance column BA.

Sheet Lists
A1: Lists (dropdown options)
A2: Overwrite the example Departments, Locations and Designations with your own. Type new options under the last item of a list. Do not delete the header row.
A4: Department | B4: Location | C4: Designation | D4: Gender | E4: Marital Status | F4: Blood Group | G4: Employment Type | H4: Exit Reason | I4: State | J4: Bank
A5: Admin | B5: Location 1 | C5: Manager | D5: Male | E5: Married | F5: A+ | G5: Permanent | H5: Resignation | I5: Andhra Pradesh | J5: State Bank of India
A6: Accounts | B6: Location 2 | C6: Executive | D6: Female | E6: Unmarried | F6: A- | G6: Probation | H6: Termination | I6: Arunachal Pradesh | J6: HDFC Bank
A7: HR | C7: Supervisor | D7: Other | E7: Divorced | F7: B+ | H7: Retirement | I7: Assam | J7: ICICI Bank
A8: IT | C8: Operator | E8: Widowed | F8: B- | H8: Absconding | I8: Bihar | J8: Axis Bank
A9: Operations | C9: Assistant | F9: O+ | H9: End of Contract | I9: Chhattisgarh | J9: Kotak Mahindra Bank
A10: Production | F10: O- | H10: Death | I10: Goa | J10: Bank of Baroda
A11: Sales | F11: AB+ | H11: Other | I11: Gujarat | J11: Punjab National Bank
A12: Stores | F12: AB- | I12: Haryana | J12: Canara Bank
I13: Himachal Pradesh | J13: Union Bank of India
I14: Jharkhand | J14: Bank of India
I15: Karnataka | J15: IDFC First Bank
I16: Kerala | J16: Indian Bank
I17: Madhya Pradesh | J17: IndusInd Bank
I18: Maharashtra | J18: Yes Bank
I19: Manipur | J19: Central Bank of India
I20: Meghalaya | J20: UCO Bank
I21: Mizoram | J21: Bank of Maharashtra
I22: Nagaland | J22: Punjab And Sind Bank
I23: Odisha | J23: Indian Overseas Bank
I24: Punjab | J24: Federal Bank
... I29: Tripura | J29: Other
I30: Uttar Pradesh
I31: Uttarakhand
I32: West Bengal
I33: Delhi
I34: Jammu and Kashmir
I35: Ladakh
I36: Chandigarh
I37: Puducherry
I38: Andaman and Nicobar Islands
I39: Dadra and Nagar Haveli and Daman and Diu
I40: Lakshadweep
