Workbook

Sheet Guide
B1: HOLIDAY WORKING ROSTER TEMPLATE - START HERE
B2: Roster for employees working on a holiday, with a location-wise summary and an annual holiday calendar. Empty and ready to fill.
B4: SHEETS
B5: Holiday Summary | C5: Holiday name and dates, location-wise count of employees working (Comp-Off / Extra Pay), and an annual holiday calendar.
B6: Holiday Roster | C6: One row per employee working on the holiday: code, name, department, designation, location, shift, contact, compensation, remarks / signature.
B7: Settings | C7: Company name (used in the titles).
B8: Lists | C8: Dropdown options for Department, Designation, Location, Compensation and Holiday Type.
B10: HOW TO USE
B11: 1. Settings / Lists | C11: Type your Company name and replace the example Departments, Locations and Designations.
B12: 2. Holiday Summary | C12: Enter the Holiday Name, Start Date and End Date in the yellow cells. Optionally fill the annual holiday calendar below.
B13: 3. Holiday Roster | C13: List each employee working: type the code, name and contact, and pick Department, Designation, Location and Compensation (Comp-Off / Extra Pay). Rows are numbered automatically.
B14: 4. Summary counts | C14: Location-wise totals on Holiday Summary update by themselves.
B15: Next holiday | C15: Clear the yellow roster cells and change the holiday details - or save a copy of the file for each holiday.
B16: Printing | C16: Both sheets are set to landscape for printing and signatures.
B18: COLOUR GUIDE
B19: Yellow cell, blue text | C19: Input cell - type here.
B20: Blue-grey cell | C20: Calculated automatically - do not type over it.
B22: LIMITS
B23: Capacity | C23: Holiday Roster: 200 employees per holiday. Holiday calendar: 30 holidays. Locations: 10.

Sheet Holiday Summary
A1: =Settings!$C$5&" - Holiday Working Roster: Location-wise Summary" -> Your Company Name - Holiday Working Roster: Location-wise Summary
A2: Fill the yellow cells. Then list the employees working on this holiday in the Holiday Roster sheet. For the next holiday, clear the yellow roster cells and change the holiday details here (or save a copy of the file).
A3: Holiday Name:
A4: Holiday Start Date:
A5: Holiday End Date:
A6: Total Holiday Days: | B6: =IF(AND(ISNUMBER(B4),ISNUMBER(B5)),B5-B4+1,"")
A8: Sr No | B8: Location | C8: Employees Working | D8: Comp-Off | E8: Extra Pay
A9: =IF(B9="","",1) -> 1 | B9: =IF(Lists!B5="","",Lists!B5) -> Location 1 | C9: =IF(B9="","",COUNTIF('Holiday Roster'!$F$6:$F$205,B9)) -> 0 | D9: =IF(B9="","",COUNTIFS('Holiday Roster'!$F$6:$F$205,B9,'Holiday Roster'!$I$6:$I$205,"Comp-Off")) -> 0 | E9: =IF(B9="","",COUNTIFS('Holiday Roster'!$F$6:$F$205,B9,'Holiday Roster'!$I$6:$I$205,"Extra Pay")) -> 0
A10: =IF(B10="","",2) -> 2 | B10: =IF(Lists!B6="","",Lists!B6) -> Location 2 | C10: =IF(B10="","",COUNTIF('Holiday Roster'!$F$6:$F$205,B10)) -> 0 | D10: =IF(B10="","",COUNTIFS('Holiday Roster'!$F$6:$F$205,B10,'Holiday Roster'!$I$6:$I$205,"Comp-Off")) -> 0 | E10: =IF(B10="","",COUNTIFS('Holiday Roster'!$F$6:$F$205,B10,'Holiday Roster'!$I$6:$I$205,"Extra Pay")) -> 0
A11: =IF(B11="","",3) | B11: =IF(Lists!B7="","",Lists!B7) | C11: =IF(B11="","",COUNTIF('Holiday Roster'!$F$6:$F$205,B11)) | D11: =IF(B11="","",COUNTIFS('Holiday Roster'!$F$6:$F$205,B11,'Holiday Roster'!$I$6:$I$205,"Comp-Off")) | E11: =IF(B11="","",COUNTIFS('Holiday Roster'!$F$6:$F$205,B11,'Holiday Roster'!$I$6:$I$205,"Extra Pay"))
A12: =IF(B12="","",4) | B12: =IF(Lists!B8="","",Lists!B8) | C12: =IF(B12="","",COUNTIF('Holiday Roster'!$F$6:$F$205,B12)) | D12: =IF(B12="","",COUNTIFS('Holiday Roster'!$F$6:$F$205,B12,'Holiday Roster'!$I$6:$I$205,"Comp-Off")) | E12: =IF(B12="","",COUNTIFS('Holiday Roster'!$F$6:$F$205,B12,'Holiday Roster'!$I$6:$I$205,"Extra Pay"))
A13: =IF(B13="","",5) | B13: =IF(Lists!B9="","",Lists!B9) | C13: =IF(B13="","",COUNTIF('Holiday Roster'!$F$6:$F$205,B13)) | D13: =IF(B13="","",COUNTIFS('Holiday Roster'!$F$6:$F$205,B13,'Holiday Roster'!$I$6:$I$205,"Comp-Off")) | E13: =IF(B13="","",COUNTIFS('Holiday Roster'!$F$6:$F$205,B13,'Holiday Roster'!$I$6:$I$205,"Extra Pay"))
A14: =IF(B14="","",6) | B14: =IF(Lists!B10="","",Lists!B10) | C14: =IF(B14="","",COUNTIF('Holiday Roster'!$F$6:$F$205,B14)) | D14: =IF(B14="","",COUNTIFS('Holiday Roster'!$F$6:$F$205,B14,'Holiday Roster'!$I$6:$I$205,"Comp-Off")) | E14: =IF(B14="","",COUNTIFS('Holiday Roster'!$F$6:$F$205,B14,'Holiday Roster'!$I$6:$I$205,"Extra Pay"))
A15: =IF(B15="","",7) | B15: =IF(Lists!B11="","",Lists!B11) | C15: =IF(B15="","",COUNTIF('Holiday Roster'!$F$6:$F$205,B15)) | D15: =IF(B15="","",COUNTIFS('Holiday Roster'!$F$6:$F$205,B15,'Holiday Roster'!$I$6:$I$205,"Comp-Off")) | E15: =IF(B15="","",COUNTIFS('Holiday Roster'!$F$6:$F$205,B15,'Holiday Roster'!$I$6:$I$205,"Extra Pay"))
A16: =IF(B16="","",8) | B16: =IF(Lists!B12="","",Lists!B12) | C16: =IF(B16="","",COUNTIF('Holiday Roster'!$F$6:$F$205,B16)) | D16: =IF(B16="","",COUNTIFS('Holiday Roster'!$F$6:$F$205,B16,'Holiday Roster'!$I$6:$I$205,"Comp-Off")) | E16: =IF(B16="","",COUNTIFS('Holiday Roster'!$F$6:$F$205,B16,'Holiday Roster'!$I$6:$I$205,"Extra Pay"))
A17: =IF(B17="","",9) | B17: =IF(Lists!B13="","",Lists!B13) | C17: =IF(B17="","",COUNTIF('Holiday Roster'!$F$6:$F$205,B17)) | D17: =IF(B17="","",COUNTIFS('Holiday Roster'!$F$6:$F$205,B17,'Holiday Roster'!$I$6:$I$205,"Comp-Off")) | E17: =IF(B17="","",COUNTIFS('Holiday Roster'!$F$6:$F$205,B17,'Holiday Roster'!$I$6:$I$205,"Extra Pay"))
A18: =IF(B18="","",10) | B18: =IF(Lists!B14="","",Lists!B14) | C18: =IF(B18="","",COUNTIF('Holiday Roster'!$F$6:$F$205,B18)) | D18: =IF(B18="","",COUNTIFS('Holiday Roster'!$F$6:$F$205,B18,'Holiday Roster'!$I$6:$I$205,"Comp-Off")) | E18: =IF(B18="","",COUNTIFS('Holiday Roster'!$F$6:$F$205,B18,'Holiday Roster'!$I$6:$I$205,"Extra Pay"))
B19: Grand Total | C19: =SUM(C9:C18) -> 0 | D19: =SUM(D9:D18) -> 0 | E19: =SUM(E9:E18) -> 0
A20: ="Roster rows with a location not in the Lists sheet: "&(COUNTA('Holiday Roster'!$B$6:$B$205)-C19) -> Roster rows with a location not in the Lists sheet: 0
A22: ANNUAL HOLIDAY CALENDAR
A23: Sr No | B23: Date | C23: Day | D23: Holiday Name | E23: Type | F23: Remarks
A24: =IF(B24="","",1) | C24: =IF(B24="","",TEXT(B24,"dddd"))
A25: =IF(B25="","",2) | C25: =IF(B25="","",TEXT(B25,"dddd"))
A26: =IF(B26="","",3) | C26: =IF(B26="","",TEXT(B26,"dddd"))
A27: =IF(B27="","",4) | C27: =IF(B27="","",TEXT(B27,"dddd"))
A28: =IF(B28="","",5) | C28: =IF(B28="","",TEXT(B28,"dddd"))
A29: =IF(B29="","",6) | C29: =IF(B29="","",TEXT(B29,"dddd"))
A30: =IF(B30="","",7) | C30: =IF(B30="","",TEXT(B30,"dddd"))
A31: =IF(B31="","",8) | C31: =IF(B31="","",TEXT(B31,"dddd"))
A32: =IF(B32="","",9) | C32: =IF(B32="","",TEXT(B32,"dddd"))
A33: =IF(B33="","",10) | C33: =IF(B33="","",TEXT(B33,"dddd"))
A34: =IF(B34="","",11) | C34: =IF(B34="","",TEXT(B34,"dddd"))
A35: =IF(B35="","",12) | C35: =IF(B35="","",TEXT(B35,"dddd"))
A36: =IF(B36="","",13) | C36: =IF(B36="","",TEXT(B36,"dddd"))
A37: =IF(B37="","",14) | C37: =IF(B37="","",TEXT(B37,"dddd"))
A38: =IF(B38="","",15) | C38: =IF(B38="","",TEXT(B38,"dddd"))
A39: =IF(B39="","",16) | C39: =IF(B39="","",TEXT(B39,"dddd"))
A40: =IF(B40="","",17) | C40: =IF(B40="","",TEXT(B40,"dddd"))
A41: =IF(B41="","",18) | C41: =IF(B41="","",TEXT(B41,"dddd"))
A42: =IF(B42="","",19) | C42: =IF(B42="","",TEXT(B42,"dddd"))
...

Sheet Holiday Roster
A1: =Settings!$C$5&" - Holiday Working Roster" -> Your Company Name - Holiday Working Roster
A2: ="Holiday: "&IF('Holiday Summary'!B3="","(enter on Holiday Summary)",'Holiday Summary'!B3)&" | "&IF(ISNUMBER('Holiday Summary'!B4),TEXT('Holiday Summary'!B4,"dd-mmm-yyyy"),"")&" to "&IF(ISNUMBER('Holiday Summary'!B5),TEXT('Holiday Summary'!B5,"dd-mmm-yyyy"),"")&" | Days: "&'Holiday Summary'!B6 -> Holiday: (enter on Holiday Summary) | to | Days:
A3: Legend: yellow cells are for entry. One row per employee working on the holiday. Department, Designation and Location have dropdowns (edit them in the Lists sheet).
A5: Sr No | B5: Emp Code | C5: Employee Name | D5: Department | E5: Designation | F5: Location | G5: Shift Timing | H5: Contact No. | I5: Compensation | J5: Remarks / Signature
A6: =IF($B6="","",ROW()-5)
A7: =IF($B7="","",ROW()-5)
A8: =IF($B8="","",ROW()-5)
A9: =IF($B9="","",ROW()-5)
A10: =IF($B10="","",ROW()-5)
A11: =IF($B11="","",ROW()-5)
A12: =IF($B12="","",ROW()-5)
A13: =IF($B13="","",ROW()-5)
A14: =IF($B14="","",ROW()-5)
A15: =IF($B15="","",ROW()-5)
A16: =IF($B16="","",ROW()-5)
A17: =IF($B17="","",ROW()-5)
... A205: =IF($B205="","",ROW()-5)

Sheet Settings
B1: Settings & Legend
B2: Yellow cells with blue text are inputs - edit them and every sheet recalculates.
B4: Setting | C4: Value | D4: Note
B5: Company name | C5: Your Company Name | D5: Appears in the titles of every sheet.
B6: Report / As-of date | C6: =TODAY() -> 46322 | D6: Auto = today. Type a fixed date to freeze age / tenure / birthday calculations.
B7: Leave year | C7: =YEAR(C6) -> 2026 | D7: Auto = year of the report date. Type a year (e.g. 2026) to fix it. Carry-forward PL is entered in Leave Record.
B8: Current financial year (auto) | C8: =IF(MONTH(C6)>=4,YEAR(C6),YEAR(C6)-1)&"-"&RIGHT(IF(MONTH(C6)>=4,YEAR(C6),YEAR(C6)-1)+1,2) -> 2026-27 | D8: Apr-Mar. Used for joiners / exits this FY.
B9: Leave as-of date (auto) | C9: =MIN(C6,DATE(C7,12,31)) -> 46322 | D9: Report date capped at the leave-year end.
B10: CL (Casual Leave) per year | C10: 7 | D10: Default from your Leave Tracker template.
B11: SL (Sick Leave) per year | C11: 7 | D11: Default from your Leave Tracker template.
B12: PL (Paid Leave) per year | C12: 18 | D12: Accrued pro-rata: PL/365 per day from the eligibility date (rounded down to 0.5).
B13: Confirmation period (days after DOJ) | C13: 90 | D13: Leave starts after confirmation (DOJ + this many days). Also sets Employment Type: Permanent after this many days from DOJ, otherwise Probation.
B14: Training days per year (per employee) | C14: 0 | D14: ASSUMPTION: set to your training policy (0 = none).
B15: "LOW" alert when total pending (CL+SL+PL) is at or below | C15: 3 | D15: Flags employees on the Dashboard attention list.
B16: Free late marks per month before deduction | C16: 3 | D16: Default from your Leave Tracker template.
B17: Deduction per extra late mark (days) | C17: 0.5 | D17: Default from your Leave Tracker template.
B18: Birthday / anniversary alert window (days) | C18: 30 | D18: Dashboard counts birthdays and work anniversaries within this many days.
B21: Attendance codes (type or pick from the dropdown in the day cells of the Attendance sheet)
B22: Code | C22: Meaning | D22: Effect on payable days / leave balance
B23: P | C23: Present | D23: 1 payable day
B24: A | C24: Absent | D24: Not paid
B25: HA | C25: Half-day absent | D25: 0.5 payable day
B26: L | C26: Late | D26: 1 payable day; counts toward late deduction
B27: PL | C27: Paid Leave | D27: 1 payable day; 1 deducted from PL balance
B28: HPL | C28: Half-day Paid Leave | D28: 1 payable day (0.5 leave + 0.5 worked); 0.5 deducted from PL balance
B29: CL | C29: Casual Leave | D29: 1 payable day; 1 deducted from CL balance
B30: HCL | C30: Half-day Casual Leave | D30: 1 payable day (0.5 leave + 0.5 worked); 0.5 deducted from CL balance
B31: SL | C31: Sick Leave | D31: 1 payable day; 1 deducted from SL balance
B32: CO | C32: Compensatory Off | D32: 1 payable day
B33: WO | C33: Weekly Off | D33: 1 payable day
... B35: TR | C35: Training Day | D35: 1 payable day; counted against Training days balance
B37: Note: half-day codes (HA, HPL, HCL) are treated as shown above. If your payroll rule is different, edit the Gross Payable Days formula in Attendance column BA.

Sheet Lists
A1: Lists (dropdown options)
A2: Overwrite the example Departments, Locations and Designations with your own. Type new options under the last item of a list. Do not delete the header row.
A4: Department | B4: Location | C4: Designation | D4: Holiday Compensation | E4: Holiday Type
A5: Admin | B5: Location 1 | C5: Manager | D5: Comp-Off | E5: National
A6: Accounts | B6: Location 2 | C6: Executive | D6: Extra Pay | E6: Festival
A7: HR | C7: Supervisor | E7: Optional
A8: IT | C8: Operator | E8: Company
A9: Operations | C9: Assistant
A10: Production
A11: Sales
A12: Stores
